Workbook

Sheet Session Feedback
A1: Respondent ID | B1: Date | C1: Venture Name | D1: Program Tier | E1: Hub | F1: Mentor Name | G1: Overall Rating (1-5) | H1: How useful was this mentor session for your current business priorities? | I1: Actionability of Advice | J1: Follow-Up Requested? | K1: Verbatim Feedback | L1: Flagged (≤3)? | M1: Action Taken | N1: Response Category | O1: Feedback category | P1: Remarks | Q1: Resolved? | R1: Reviewed In Stand-Up? | S1: # How useful was this mentor session for your current business priorities? | T1: # Actionability of Advice | U1: # Follow-Up Requested? | V1: Date (Week)
A2: 115104773879 | B2: 46163 | C2: Rupiya Finnovations Pvt Ltd | D2: Accelerate Core | E2: Ahmedabad | F2: Srinivas Yanamandra | G2: =AVERAGE(S2:T2) -> 4.5 | H2: Very useful | I2: Yes | J2: Yes | K2: The session was good and wanted to connect with him again. | S2: =IF(H2="Extremely useful",5,IF(H2="Very useful",4,IF(H2="Moderately useful",3,IF(H2="Slightly useful",2,IF(H2="Not useful",1))))) -> 4 | T2: =IF(I2="Yes",5,IF(I2="Partly",3,IF(I2="No",1))) -> 5 | U2: =IF(J2="Yes",5,IF(J2="No",1)) -> 5 | V2: =IF(ISBLANK(FeedbackTracker[[#This Row],[Date]]),"",INT(FeedbackTracker[[#This Row],[Date]]-WEEKDAY(FeedbackTracker[[#This Row],[Date]],2)+1)) -> 46160
A3: 115100331078 | B3: 46156 | C3: Tikitoro | D3: Accelerate Core | E3: Chennai | F3: Gaurav Bansal | G3: =AVERAGE(S3:T3) -> 3.5 | H3: Very useful | I3: Partly | J3: Yes | K3: The mentor was good and want to meet him even but will fix the agenda and if he agrees that he will be fit for that then only I need a call with him. | O3: 1st Intro call | S3: =IF(H3="Extremely useful",5,IF(H3="Very useful",4,IF(H3="Moderately useful",3,IF(H3="Slightly useful",2,IF(H3="Not useful",1))))) -> 4 | T3: =IF(I3="Yes",5,IF(I3="Partly",3,IF(I3="No",1))) -> 3 | U3: =IF(J3="Yes",5,IF(J3="No",1)) -> 5 | V3: =IF(ISBLANK(FeedbackTracker[[#This Row],[Date]]),"",INT(FeedbackTracker[[#This Row],[Date]]-WEEKDAY(FeedbackTracker[[#This Row],[Date]],2)+1)) -> 46153
A4: 115101125450 | B4: 46157 | C4: Terrablu | D4: Accelerate Core | E4: Pune | F4: Anant Sood | G4: =AVERAGE(S4:T4) -> 4.5 | H4: Very useful | I4: Yes | J4: Yes | K4: The session was good. The clearity with which Mr. sood was taking session was beyond imagination. | L4: Yes | S4: =IF(H4="Extremely useful",5,IF(H4="Very useful",4,IF(H4="Moderately useful",3,IF(H4="Slightly useful",2,IF(H4="Not useful",1))))) -> 4 | T4: =IF(I4="Yes",5,IF(I4="Partly",3,IF(I4="No",1))) -> 5 | U4: =IF(J4="Yes",5,IF(J4="No",1)) -> 5 | V4: =IF(ISBLANK(FeedbackTracker[[#This Row],[Date]]),"",INT(FeedbackTracker[[#This Row],[Date]]-WEEKDAY(FeedbackTracker[[#This Row],[Date]],2)+1)) -> 46153
A5: 115100263275 | B5: 46156 | C5: Eximburg International | D5: Accelerate Core | E5: Ahmedabad | F5: Kushagra Gupta | G5: =AVERAGE(S5:T5) -> 3.5 | H5: Very useful | I5: Partly | J5: No | K5: The mentor was good but same as mentioned earlier we needed somebody to audit our amazon account. | L5: =IF(G5<=3,"Yes","No") -> No | N5: Received | P5: 14-May-2026: Venture denied for another session with mentor | S5: =IF(H5="Extremely useful",5,IF(H5="Very useful",4,IF(H5="Moderately useful",3,IF(H5="Slightly useful",2,IF(H5="Not useful",1))))) -> 4 | T5: =IF(I5="Yes",5,IF(I5="Partly",3,IF(I5="No",1))) -> 3 | U5: =IF(J5="Yes",5,IF(J5="No",1)) -> 1 | V5: =IF(ISBLANK(FeedbackTracker[[#This Row],[Date]]),"",INT(FeedbackTracker[[#This Row],[Date]]-WEEKDAY(FeedbackTracker[[#This Row],[Date]],2)+1)) -> 46153
A6: 115100253848 | B6: 46156 | C6: Eximburg International | D6: Accelerate Core | E6: Ahmedabad | F6: Sriram Chidambaram | G6: =AVERAGE(S6:T6) -> 4.5 | H6: Very useful | I6: Yes | J6: No | K6: It was meaningful sssion but we want to more sessions about the valuation. | S6: =IF(H6="Extremely useful",5,IF(H6="Very useful",4,IF(H6="Moderately useful",3,IF(H6="Slightly useful",2,IF(H6="Not useful",1))))) -> 4 | T6: =IF(I6="Yes",5,IF(I6="Partly",3,IF(I6="No",1))) -> 5 | U6: =IF(J6="Yes",5,IF(J6="No",1)) -> 1 | V6: =IF(ISBLANK(FeedbackTracker[[#This Row],[Date]]),"",INT(FeedbackTracker[[#This Row],[Date]]-WEEKDAY(FeedbackTracker[[#This Row],[Date]],2)+1)) -> 46153
A7: 115100236156 | B7: 46156 | C7: Zeus Engitech Private Limited | D7: Accelerate Core | E7: Ahmedabad | F7: Ankit Majumdar | G7: =AVERAGE(S7:T7) -> 4 | H7: Moderately useful | I7: Yes | J7: Yes | K7: I selected “Moderately” because I would like to first implement the insights and suggestions shared, and then evaluate how effective they are. Overall, the session was very good. | L7: =IF(G7<=3,"Yes","No") -> No | N7: Received | P7: 13-Apr-2026: The mentor was good, but they wanted to see if the suggestions are truely useful at time of implementation. | S7: =IF(H7="Extremely useful",5,IF(H7="Very useful",4,IF(H7="Moderately useful",3,IF(H7="Slightly useful",2,IF(H7="Not useful",1))))) -> 3 | T7: =IF(I7="Yes",5,IF(I7="Partly",3,IF(I7="No",1))) -> 5 | U7: =IF(J7="Yes",5,IF(J7="No",1)) -> 5 | V7: =IF(ISBLANK(FeedbackTracker[[#This Row],[Date]]),"",INT(FeedbackTracker[[#This Row],[Date]]-WEEKDAY(FeedbackTracker[[#This Row],[Date]],2)+1)) -> 46153
A8: 115099419177 | B8: 46155 | C8: Manufyx | D8: Accelerate Core | E8: Chennai | F8: Sanjay Sharma | G8: =AVERAGE(S8:T8) -> 4.5 | H8: Very useful | I8: Yes | J8: No | K8: The session was very nice and Wadhwani is giving us what we need. | L8: =IF(G8<=3,"Yes","No") -> No | P8: 13-May-2026: Venture denied for another session with mentor | S8: =IF(H8="Extremely useful",5,IF(H8="Very useful",4,IF(H8="Moderately useful",3,IF(H8="Slightly useful",2,IF(H8="Not useful",1))))) -> 4 | T8: =IF(I8="Yes",5,IF(I8="Partly",3,IF(I8="No",1))) -> 5 | U8: =IF(J8="Yes",5,IF(J8="No",1)) -> 1 | V8: =IF(ISBLANK(FeedbackTracker[[#This Row],[Date]]),"",INT(FeedbackTracker[[#This Row],[Date]]-WEEKDAY(FeedbackTracker[[#This Row],[Date]],2)+1)) -> 46153
A9: 115099491986 | B9: 46155 | C9: Sarumam Pharmacy | D9: Accelerate Core | E9: Chennai | F9: Ajay Rungta | G9: =AVERAGE(S9:T9) -> 4.5 | H9: Very useful | I9: Yes | J9: Yes | K9: He was able to identify what I needed and provided the solutions to me immediately. | L9: =IF(G9<=3,"Yes","No") -> No | S9: =IF(H9="Extremely useful",5,IF(H9="Very useful",4,IF(H9="Moderately useful",3,IF(H9="Slightly useful",2,IF(H9="Not useful",1))))) -> 4 | T9: =IF(I9="Yes",5,IF(I9="Partly",3,IF(I9="No",1))) -> 5 | U9: =IF(J9="Yes",5,IF(J9="No",1)) -> 5 | V9: =IF(ISBLANK(FeedbackTracker[[#This Row],[Date]]),"",INT(FeedbackTracker[[#This Row],[Date]]-WEEKDAY(FeedbackTracker[[#This Row],[Date]],2)+1)) -> 46153
A10: 115097528792 | B10: 46153 | C10: REAGRI - NANOBEE BIOINNOVATIONS | D10: Accelerate Core | E10: Ahmedabad | F10: Suhasini Barman | G10: =AVERAGE(S10:T10) -> 4.5 | H10: Very useful | I10: Yes | J10: Yes | K10: The session was very useful. | L10: No | S10: =IF(H10="Extremely useful",5,IF(H10="Very useful",4,IF(H10="Moderately useful",3,IF(H10="Slightly useful",2,IF(H10="Not useful",1))))) -> 4 | T10: =IF(I10="Yes",5,IF(I10="Partly",3,IF(I10="No",1))) -> 5 | U10: =IF(J10="Yes",5,IF(J10="No",1)) -> 5 | V10: =IF(ISBLANK(FeedbackTracker[[#This Row],[Date]]),"",INT(FeedbackTracker[[#This Row],[Date]]-WEEKDAY(FeedbackTracker[[#This Row],[Date]],2)+1)) -> 46153
A11: 115095338090 | B11: 46149 | C11: VideoSDK | D11: Accelerate Core | E11: Ahmedabad | F11: Mithun Kumar Mahendra | G11: =AVERAGE(S11:T11) -> 5 | H11: Extremely useful | I11: Yes | J11: No | K11: The session was very amazing. Wanted to connect to other mentor that is Mr. Sid Pandey. | L11: No | S11: =IF(H11="Extremely useful",5,IF(H11="Very useful",4,IF(H11="Moderately useful",3,IF(H11="Slightly useful",2,IF(H11="Not useful",1))))) -> 5 | T11: =IF(I11="Yes",5,IF(I11="Partly",3,IF(I11="No",1))) -> 5 | U11: =IF(J11="Yes",5,IF(J11="No",1)) -> 1 | V11: =IF(ISBLANK(FeedbackTracker[[#This Row],[Date]]),"",INT(FeedbackTracker[[#This Row],[Date]]-WEEKDAY(FeedbackTracker[[#This Row],[Date]],2)+1)) -> 46146
A12: 115095310455 | B12: 46149 | C12: Leap Info | D12: Accelerate Core | E12: Pune | F12: Dr. Naman Agarwal | G12: =AVERAGE(S12:T12) -> 3 | H12: Moderately useful | I12: Partly | J12: No | K12: I was expecting insights on business opportunities from the Netherlands side, but the discussion was mostly around Indian government startup schemes. | L12: No | M12: Reached out: Response Received | N12: Received | O12: 1st Intro Call | P12: 7-May-2026: The venture shared that they were expecting more discussion around Netherlands-side business opportunities, since the expert was from the Netherlands Embassy. However, they had been connected with Naman specifically for IP and patent-related guidance, and they found the session informative overall. We also checked if they wanted any further mentor connect, but currently they don’t have any additional requirements. | S12: =IF(H12="Extremely useful",5,IF(H12="Very useful",4,IF(H12="Moderately useful",3,IF(H12="Slightly useful",2,IF(H12="Not useful",1))))) -> 3 | T12: =IF(I12="Yes",5,IF(I12="Partly",3,IF(I12="No",1))) -> 3 | U12: =IF(J12="Yes",5,IF(J12="No",1)) -> 1 | V12: =IF(ISBLANK(FeedbackTracker[[#This Row],[Date]]),"",INT(FeedbackTracker[[#This Row],[Date]]-WEEKDAY(FeedbackTracker[[#This Row],[Date]],2)+1)) -> 46146
A13: 115092759158 | B13: 46146 | C13: Svan Autotech | D13: Accelerate Core | E13: Ahmedabad | F13: Sriram Chidambaram | G13: =AVERAGE(S13:T13) -> 5 | H13: Extremely useful | I13: Yes | J13: Yes | K13: We want to take his help in making the financial projections. It will greatly help us close the current round. | L13: No | S13: =IF(H13="Extremely useful",5,IF(H13="Very useful",4,IF(H13="Moderately useful",3,IF(H13="Slightly useful",2,IF(H13="Not useful",1))))) -> 5 | T13: =IF(I13="Yes",5,IF(I13="Partly",3,IF(I13="No",1))) -> 5 | U13: =IF(J13="Yes",5,IF(J13="No",1)) -> 5 | V13: =IF(ISBLANK(FeedbackTracker[[#This Row],[Date]]),"",INT(FeedbackTracker[[#This Row],[Date]]-WEEKDAY(FeedbackTracker[[#This Row],[Date]],2)+1)) -> 46146
A14: 115084318304 | B14: 46134 | C14: Keepsake Automation Pvt Ltd | D14: Accelerate Core | E14: Ahmedabad | F14: Garima Mitra | G14: =AVERAGE(S14:T14) -> 3 | H14: Moderately useful | I14: Partly | J14: No | K14: Mentor offered us paid services for advice and we don't | L14: Yes | M14: Reached out: Response Received | N14: Received | O14: Misalignment | P14: 22-Apr-2026: The services or fees mentioned by Garima are strictly related to legal documentation and other legal matters. The fee has been charged solely for these services, and not for anything else. We also checked the session's transcript and recording, and found that venture got the proper mentoring what was supposed to be given. | S14: =IF(H14="Extremely useful",5,IF(H14="Very useful",4,IF(H14="Moderately useful",3,IF(H14="Slightly useful",2,IF(H14="Not useful",1))))) -> 3 | T14: =IF(I14="Yes",5,IF(I14="Partly",3,IF(I14="No",1))) -> 3 | U14: =IF(J14="Yes",5,IF(J14="No",1)) -> 1 | V14: =IF(ISBLANK(FeedbackTracker[[#This Row],[Date]]),"",INT(FeedbackTracker[[#This Row],[Date]]-WEEKDAY(FeedbackTracker[[#This Row],[Date]],2)+1)) -> 46132
A15: 115084260317 | B15: 46134 | C15: Elite Decor Pvt. Ltd | D15: Accelerate Select | E15: Ahmedabad | F15: Vinod Keni | G15: =AVERAGE(S15:T15) -> 3.5 | H15: Very useful | I15: Partly | J15: Yes | K15: the sesession was good and wanted to have one more follow session with him. | L15: Yes | M15: Reached out: Response Received | N15: Received | O15: 1st Intro Call | P15: 22-Apr-2026: Wanted one more session with mentor | S15: =IF(H15="Extremely useful",5,IF(H15="Very useful",4,IF(H15="Moderately useful",3,IF(H15="Slightly useful",2,IF(H15="Not useful",1))))) -> 4 | T15: =IF(I15="Yes",5,IF(I15="Partly",3,IF(I15="No",1))) -> 3 | U15: =IF(J15="Yes",5,IF(J15="No",1)) -> 5 | V15: =IF(ISBLANK(FeedbackTracker[[#This Row],[Date]]),"",INT(FeedbackTracker[[#This Row],[Date]]-WEEKDAY(FeedbackTracker[[#This Row],[Date]],2)+1)) -> 46132
A16: 115080568744 | B16: 46128.594 | C16: MiCoB Pvt Ltd | D16: Accelerate Core | E16: Ahmedabad | F16: Amit Saluja | G16: =AVERAGE(S16:T16) -> 4 | H16: Extremely useful | I16: Partly | J16: Yes | K16: Want one more session and was very good session. | L16: =IF(G16<=3,"Yes","No") -> No | M16: Reached out: Response Received | O16: 1st Intro Call | P16: 17-04-2026: | S16: =IF(H16="Extremely useful",5,IF(H16="Very useful",4,IF(H16="Moderately useful",3,IF(H16="Slightly useful",2,IF(H16="Not useful",1))))) -> 5 | T16: =IF(I16="Yes",5,IF(I16="Partly",3,IF(I16="No",1))) -> 3 | U16: =IF(J16="Yes",5,IF(J16="No",1)) -> 5 | V16: =IF(ISBLANK(FeedbackTracker[[#This Row],[Date]]),"",INT(FeedbackTracker[[#This Row],[Date]]-WEEKDAY(FeedbackTracker[[#This Row],[Date]],2)+1)) -> 46125
A17: 115080545344 | B17: 46128.568 | C17: Torchit | D17: Accelerate Core | E17: Ahmedabad | F17: Sriram Chidambaram | G17: =AVERAGE(S17:T17) -> 4.5 | H17: Very useful | I17: Yes | J17: No | K17: The session was good and mentor is perfectly fine. | L17: =IF(G17<=3,"Yes","No") -> No | M17: Reached out: Response Received | S17: =IF(H17="Extremely useful",5,IF(H17="Very useful",4,IF(H17="Moderately useful",3,IF(H17="Slightly useful",2,IF(H17="Not useful",1))))) -> 4 | T17: =IF(I17="Yes",5,IF(I17="Partly",3,IF(I17="No",1))) -> 5 | U17: =IF(J17="Yes",5,IF(J17="No",1)) -> 1 | V17: =IF(ISBLANK(FeedbackTracker[[#This Row],[Date]]),"",INT(FeedbackTracker[[#This Row],[Date]]-WEEKDAY(FeedbackTracker[[#This Row],[Date]],2)+1)) -> 46125
A18: 115080527222 | B18: 46128.542 | C18: Bipolar Factory | D18: Accelerate Prime | E18: Chennai | F18: Sriram Chidambaram | G18: =AVERAGE(S18:T18) -> 4.5 | H18: Very useful | I18: Yes | J18: Yes | K18: It was very good session and will tell when we want to get connected again | L18: =IF(G18<=3,"Yes","No") -> No | S18: =IF(H18="Extremely useful",5,IF(H18="Very useful",4,IF(H18="Moderately useful",3,IF(H18="Slightly useful",2,IF(H18="Not useful",1))))) -> 4 | T18: =IF(I18="Yes",5,IF(I18="Partly",3,IF(I18="No",1))) -> 5 | U18: =IF(J18="Yes",5,IF(J18="No",1)) -> 5 | V18: =IF(ISBLANK(FeedbackTracker[[#This Row],[Date]]),"",INT(FeedbackTracker[[#This Row],[Date]]-WEEKDAY(FeedbackTracker[[#This Row],[Date]],2)+1)) -> 46125
A19: 115067302264 | B19: 46107.501 | C19: Tikitoro | D19: Accelerate Core | E19: Chennai | F19: Shridhar N Upadhye | G19: =AVERAGE(S19:T19) -> 5 | H19: Extremely useful | I19: Yes | J19: No | K19: Mr. Krishna Dorai was excellent and gave some great insights and executable action points in the session. It was great connecting with him. | L19: =IF(G19<=3,"Yes","No") -> No | S19: =IF(H19="Extremely useful",5,IF(H19="Very useful",4,IF(H19="Moderately useful",3,IF(H19="Slightly useful",2,IF(H19="Not useful",1))))) -> 5 | T19: =IF(I19="Yes",5,IF(I19="Partly",3,IF(I19="No",1))) -> 5 | U19: =IF(J19="Yes",5,IF(J19="No",1)) -> 1 | V19: =IF(ISBLANK(FeedbackTracker[[#This Row],[Date]]),"",INT(FeedbackTracker[[#This Row],[Date]]-WEEKDAY(FeedbackTracker[[#This Row],[Date]],2)+1)) -> 46104
A20: 115065626399 | B20: 46105.558 | C20: Stembotix | D20: Accelerate Core | E20: Ahmedabad | F20: Amiya Srivastava | G20: =AVERAGE(S20:T20) -> 4.5 | H20: Very useful | I20: Yes | J20: Yes | K20: Want to meet the mentor again in Mid April | L20: =IF(G20<=3,"Yes","No") -> No | M20: Reached out: Response Received | S20: =IF(H20="Extremely useful",5,IF(H20="Very useful",4,IF(H20="Moderately useful",3,IF(H20="Slightly useful",2,IF(H20="Not useful",1))))) -> 4 | T20: =IF(I20="Yes",5,IF(I20="Partly",3,IF(I20="No",1))) -> 5 | U20: =IF(J20="Yes",5,IF(J20="No",1)) -> 5 | V20: =IF(ISBLANK(FeedbackTracker[[#This Row],[Date]]),"",INT(FeedbackTracker[[#This Row],[Date]]-WEEKDAY(FeedbackTracker[[#This Row],[Date]],2)+1)) -> 46104
A21: 115062696710 | B21: 46100.423 | C21: Tikitoro | D21: Accelerate Core | E21: Chennai | F21: Shridhar N Upadhye | G21: =AVERAGE(S21:T21) -> 4.5 | H21: Very useful | I21: Yes | J21: Yes | K21: We discussed on clearity and looking forward to meet with mentor again. | L21: =IF(G21<=3,"Yes","No") -> No | M21: Reached out: Response Received | S21: =IF(H21="Extremely useful",5,IF(H21="Very useful",4,IF(H21="Moderately useful",3,IF(H21="Slightly useful",2,IF(H21="Not useful",1))))) -> 4 | T21: =IF(I21="Yes",5,IF(I21="Partly",3,IF(I21="No",1))) -> 5 | U21: =IF(J21="Yes",5,IF(J21="No",1)) -> 5 | V21: =IF(ISBLANK(FeedbackTracker[[#This Row],[Date]]),"",INT(FeedbackTracker[[#This Row],[Date]]-WEEKDAY(FeedbackTracker[[#This Row],[Date]],2)+1)) -> 46097
A22: 115061950102 | B22: 46099.527 | C22: Bull AgriTech | D22: Accelerate Core | E22: Ahmedabad | F22: Shailendrasinh Rajput | G22: =AVERAGE(S22:T22) -> 3.5 | H22: Very useful | I22: Partly | J22: Yes | K22: Wanted to connected with mentor again, as he is a very good fit for our requirement. | L22: =IF(G22<=3,"Yes","No") -> No | M22: Reached out: Response Received | N22: Received | O22: 1st Intro Call | P22: 18-mar-2026: The venture expected immediate advice, but as it was an introductory call, the mentor focused on understanding the venture first. | S22: =IF(H22="Extremely useful",5,IF(H22="Very useful",4,IF(H22="Moderately useful",3,IF(H22="Slightly useful",2,IF(H22="Not useful",1))))) -> 4 | T22: =IF(I22="Yes",5,IF(I22="Partly",3,IF(I22="No",1))) -> 3 | U22: =IF(J22="Yes",5,IF(J22="No",1)) -> 5 | V22: =IF(ISBLANK(FeedbackTracker[[#This Row],[Date]]),"",INT(FeedbackTracker[[#This Row],[Date]]-WEEKDAY(FeedbackTracker[[#This Row],[Date]],2)+1)) -> 46097
A23: 115060369534 | B23: 46097.433 | C23: Bebe Burp | D23: Accelerate Core | E23: Ahmedabad | F23: Bharat Hudadalli | G23: =AVERAGE(S23:T23) -> 3.5 | H23: Very useful | I23: Partly | J23: Yes | K23: The session gave us a good insight for D2C but moreover he is about to get back to us with a proposal for the service he can offer in 4 days | L23: =IF(G23<=3,"Yes","No") -> No | M23: Reached out: Response Received | N23: Received | O23: 1st Intro Call | P23: 31-mar-2026: It was an intro call that's why mentor didn't gave his feedbacks and venture wants to get connected with mentor again 26-Mar-2026: Not reachable | S23: =IF(H23="Extremely useful",5,IF(H23="Very useful",4,IF(H23="Moderately useful",3,IF(H23="Slightly useful",2,IF(H23="Not useful",1))))) -> 4 | T23: =IF(I23="Yes",5,IF(I23="Partly",3,IF(I23="No",1))) -> 3 | U23: =IF(J23="Yes",5,IF(J23="No",1)) -> 5 | V23: =IF(ISBLANK(FeedbackTracker[[#This Row],[Date]]),"",INT(FeedbackTracker[[#This Row],[Date]]-WEEKDAY(FeedbackTracker[[#This Row],[Date]],2)+1)) -> 46097
A24: 115058872547 | B24: 46094.684 | C24: Aeronero Solutions Private Limited | D24: Accelerate Core | E24: Chennai | F24: Sriram Chidambaram | G24: =AVERAGE(S24:T24) -> 3.5 | H24: Very useful | I24: Partly | J24: No | K24: I want a deep dive in some specific areas | L24: =IF(G24<=3,"Yes","No") -> No | M24: Reached out: Response Received | N24: Received | O24: Misalignment | P24: 13-Mar-2026: Venture found that mentor is suitable for early age startups but not entures like them. The knowledge was at very basic and useful for early age startups | S24: =IF(H24="Extremely useful",5,IF(H24="Very useful",4,IF(H24="Moderately useful",3,IF(H24="Slightly useful",2,IF(H24="Not useful",1))))) -> 4 | T24: =IF(I24="Yes",5,IF(I24="Partly",3,IF(I24="No",1))) -> 3 | U24: =IF(J24="Yes",5,IF(J24="No",1)) -> 1 | V24: =IF(ISBLANK(FeedbackTracker[[#This Row],[Date]]),"",INT(FeedbackTracker[[#This Row],[Date]]-WEEKDAY(FeedbackTracker[[#This Row],[Date]],2)+1)) -> 46090
A25: 115056979250 | B25: 46092.428 | C25: Vaultastic | D25: Accelerate Core | E25: Pune | F25: Deepak Srinivasan | G25: =AVERAGE(S25:T25) -> 3 | H25: Moderately useful | I25: Partly | J25: No | K25: The session was okay and we are looking more detailed for BFSI. | L25: =IF(G25<=3,"Yes","No") -> Yes | N25: Received | O25: Misalignment | P25: 26-Mar-2026: Mr. Srinivasan is an early age startup mentor, we want some mature mentors who can replicate Banking model. Informed Rishabh about this and want mentor for fundraising thing and was conveyed to Rishabh about this. | S25: =IF(H25="Extremely useful",5,IF(H25="Very useful",4,IF(H25="Moderately useful",3,IF(H25="Slightly useful",2,IF(H25="Not useful",1))))) -> 3 | T25: =IF(I25="Yes",5,IF(I25="Partly",3,IF(I25="No",1))) -> 3 | U25: =IF(J25="Yes",5,IF(J25="No",1)) -> 1 | V25: =IF(ISBLANK(FeedbackTracker[[#This Row],[Date]]),"",INT(FeedbackTracker[[#This Row],[Date]]-WEEKDAY(FeedbackTracker[[#This Row],[Date]],2)+1)) -> 46090
A26: 115056976367 | B26: 46092.418 | C26: Bebe Burp | D26: Accelerate Core | E26: Ahmedabad | F26: Bharat Hudadalli | G26: =AVERAGE(S26:T26) -> 4 | H26: Extremely useful | I26: Partly | J26: Yes | K26: Bharat really has great knowledge and want to connect with him again he has knowledge for scaleup thing | L26: =IF(G26<=3,"Yes","No") -> No | M26: Received | N26: Received | O26: 1st Intro Call | P26: 11-Mar-2026: The venture expected immediate advice, but as it was an introductory call, the mentor focused on understanding the venture first. | S26: =IF(H26="Extremely useful",5,IF(H26="Very useful",4,IF(H26="Moderately useful",3,IF(H26="Slightly useful",2,IF(H26="Not useful",1))))) -> 5 | T26: =IF(I26="Yes",5,IF(I26="Partly",3,IF(I26="No",1))) -> 3 | U26: =IF(J26="Yes",5,IF(J26="No",1)) -> 5 | V26: =IF(ISBLANK(FeedbackTracker[[#This Row],[Date]]),"",INT(FeedbackTracker[[#This Row],[Date]]-WEEKDAY(FeedbackTracker[[#This Row],[Date]],2)+1)) -> 46090
A27: 115056975802 | B27: 46092.417 | C27: Bebe Burp | D27: Accelerate Core | E27: Ahmedabad | F27: Sivesh Kumar | G27: =AVERAGE(S27:T27) -> 1.5 | H27: Slightly useful | I27: No | J27: No | K27: The session was bit confusing. | L27: =IF(G27<=3,"Yes","No") -> Yes | M27: No Response: Call Disconnected | N27: Received | O27: Misalignment | P27: 30-Mar-2026: For this only Mr. Sivesh was only suggested by Jigar. Mentor do not know much influencer led content. 26-Mar-2026: Not reachable | S27: =IF(H27="Extremely useful",5,IF(H27="Very useful",4,IF(H27="Moderately useful",3,IF(H27="Slightly useful",2,IF(H27="Not useful",1))))) -> 2 | T27: =IF(I27="Yes",5,IF(I27="Partly",3,IF(I27="No",1))) -> 1 | U27: =IF(J27="Yes",5,IF(J27="No",1)) -> 1 | V27: =IF(ISBLANK(FeedbackTracker[[#This Row],[Date]]),"",INT(FeedbackTracker[[#This Row],[Date]]-WEEKDAY(FeedbackTracker[[#This Row],[Date]],2)+1)) -> 46090
A28: 115056971880 | B28: 46092.408 | C28: Botminds.ai | D28: Accelerate Core | E28: Chennai | F28: Mahesh Natrajan | G28: =AVERAGE(S28:T28) -> 5 | H28: Extremely useful | I28: Yes | J28: No | K28: The feedback was very helpful and would like to meet the mentor in few months | L28: =IF(G28<=3,"Yes","No") -> No | M28: No Response: Call Disconnected | S28: =IF(H28="Extremely useful",5,IF(H28="Very useful",4,IF(H28="Moderately useful",3,IF(H28="Slightly useful",2,IF(H28="Not useful",1))))) -> 5 | T28: =IF(I28="Yes",5,IF(I28="Partly",3,IF(I28="No",1))) -> 5 | U28: =IF(J28="Yes",5,IF(J28="No",1)) -> 1 | V28: =IF(ISBLANK(FeedbackTracker[[#This Row],[Date]]),"",INT(FeedbackTracker[[#This Row],[Date]]-WEEKDAY(FeedbackTracker[[#This Row],[Date]],2)+1)) -> 46090
A29: 115056188745 | B29: 46091.583 | C29: Qarmatek | D29: Accelerate Core | E29: Ahmedabad | F29: Abhay Jajoo | G29: =AVERAGE(S29:T29) -> 1 | H29: Not useful | I29: No | J29: No | K29: Not at all useful | L29: =IF(G29<=3,"Yes","No") -> Yes | N29: No Response: Call Disconnected | P29: 21-Apr-2026: As were not able to reach out to Founder. We used NoteLM to get the meeting output. Added in Notes 31-Mar-2026: Founder asked to call after next week as he is busy in march closing thing 17-mar-2026: Venture rejected the call 16-mar-2026: Venture rejected the call 13-Mar-2026: Wasn't reachbale 11-mar-2026: Venture asked to call tommorow | S29: =IF(H29="Extremely useful",5,IF(H29="Very useful",4,IF(H29="Moderately useful",3,IF(H29="Slightly useful",2,IF(H29="Not useful",1))))) -> 1 | T29: =IF(I29="Yes",5,IF(I29="Partly",3,IF(I29="No",1))) -> 1 | U29: =IF(J29="Yes",5,IF(J29="No",1)) -> 1 | V29: =IF(ISBLANK(FeedbackTracker[[#This Row],[Date]]),"",INT(FeedbackTracker[[#This Row],[Date]]-WEEKDAY(FeedbackTracker[[#This Row],[Date]],2)+1)) -> 46090
A30: 115056187941 | B30: 46091.582 | C30: Qarmatek | D30: Accelerate Core | E30: Ahmedabad | F30: Nirmallya Roy Chowdhury | G30: =AVERAGE(S30:T30) -> 3 | H30: Moderately useful | I30: Partly | J30: Yes | K30: He was going to get back with a questionairre but he hasn't - so if you could speak with him and check out his interest ? i would be glad to speak with him again | L30: =IF(G30<=3,"Yes","No") -> Yes | N30: No Response: Call Disconnected | P30: 31-Mar-2026: Founder asked to call after next week as he is busy in march closing thing 17-mar-2026: Venture rejected the call 16-mar-2026: Venture rejected the call 13-Mar-2026: Wasn't reachbale 11-mar-2026: Venture asked to call tommorow | S30: =IF(H30="Extremely useful",5,IF(H30="Very useful",4,IF(H30="Moderately useful",3,IF(H30="Slightly useful",2,IF(H30="Not useful",1))))) -> 3 | T30: =IF(I30="Yes",5,IF(I30="Partly",3,IF(I30="No",1))) -> 3 | U30: =IF(J30="Yes",5,IF(J30="No",1)) -> 5 | V30: =IF(ISBLANK(FeedbackTracker[[#This Row],[Date]]),"",INT(FeedbackTracker[[#This Row],[Date]]-WEEKDAY(FeedbackTracker[[#This Row],[Date]],2)+1)) -> 46090
A31: 115056187584 | B31: 46091.578 | C31: Qarmatek | D31: Accelerate Core | E31: Ahmedabad | F31: Anant Sood | G31: =AVERAGE(S31:T31) -> 2.5 | H31: Slightly useful | I31: Partly | J31: No | K31: he was supposed to get back but he never did so won't be going forward with him | L31: =IF(G31<=3,"Yes","No") -> Yes | N31: No Response: Call Disconnected | P31: 31-Mar-2026: Founder asked to call after next week as he is busy in march closing thing 17-mar-2026: Venture rejected the call 16-mar-2026: Venture rejected the call 13-Mar-2026: Wasn't reachbale 11-mar-2026: Venture asked to call tommorow | S31: =IF(H31="Extremely useful",5,IF(H31="Very useful",4,IF(H31="Moderately useful",3,IF(H31="Slightly useful",2,IF(H31="Not useful",1))))) -> 2 | T31: =IF(I31="Yes",5,IF(I31="Partly",3,IF(I31="No",1))) -> 3 | U31: =IF(J31="Yes",5,IF(J31="No",1)) -> 1 | V31: =IF(ISBLANK(FeedbackTracker[[#This Row],[Date]]),"",INT(FeedbackTracker[[#This Row],[Date]]-WEEKDAY(FeedbackTracker[[#This Row],[Date]],2)+1)) -> 46090
A32: 115056185661 | B32: 46091.577 | C32: Qarmatek | D32: Accelerate Core | E32: Ahmedabad | F32: Ashesh D Shah | G32: =AVERAGE(S32:T32) -> 5 | H32: Extremely useful | I32: Yes | J32: No | K32: I have already signed up with Ashesh bhai for the next steps | L32: =IF(G32<=3,"Yes","No") -> No | S32: =IF(H32="Extremely useful",5,IF(H32="Very useful",4,IF(H32="Moderately useful",3,IF(H32="Slightly useful",2,IF(H32="Not useful",1))))) -> 5 | T32: =IF(I32="Yes",5,IF(I32="Partly",3,IF(I32="No",1))) -> 5 | U32: =IF(J32="Yes",5,IF(J32="No",1)) -> 1 | V32: =IF(ISBLANK(FeedbackTracker[[#This Row],[Date]]),"",INT(FeedbackTracker[[#This Row],[Date]]-WEEKDAY(FeedbackTracker[[#This Row],[Date]],2)+1)) -> 46090
A33: 115042914743 | B33: 46071.393 | C33: Agriown Farmtech | D33: Accelerate Core | E33: Ahmedabad | F33: Sriram Chidambaram | G33: =AVERAGE(S33:T33) -> 4.5 | H33: Very useful | I33: Yes | J33: No | K33: The experience was very good and very helpful to us | L33: =IF(G33<=3,"Yes","No") -> No | M33: Reached out: Response Received | S33: =IF(H33="Extremely useful",5,IF(H33="Very useful",4,IF(H33="Moderately useful",3,IF(H33="Slightly useful",2,IF(H33="Not useful",1))))) -> 4 | T33: =IF(I33="Yes",5,IF(I33="Partly",3,IF(I33="No",1))) -> 5 | U33: =IF(J33="Yes",5,IF(J33="No",1)) -> 1 | V33: =IF(ISBLANK(FeedbackTracker[[#This Row],[Date]]),"",INT(FeedbackTracker[[#This Row],[Date]]-WEEKDAY(FeedbackTracker[[#This Row],[Date]],2)+1)) -> 46069
A34: 115042911097 | B34: 46071.407 | C34: Myharvest Farms | D34: Accelerate Prime | E34: Chennai | F34: Nirmallya Roy Chowdhury | G34: =AVERAGE(S34:T34) -> 4.5 | H34: Very useful | I34: Yes | J34: No | K34: It was just an intro call and was good. | L34: =IF(G34<=3,"Yes","No") -> No | S34: =IF(H34="Extremely useful",5,IF(H34="Very useful",4,IF(H34="Moderately useful",3,IF(H34="Slightly useful",2,IF(H34="Not useful",1))))) -> 4 | T34: =IF(I34="Yes",5,IF(I34="Partly",3,IF(I34="No",1))) -> 5 | U34: =IF(J34="Yes",5,IF(J34="No",1)) -> 1 | V34: =IF(ISBLANK(FeedbackTracker[[#This Row],[Date]]),"",INT(FeedbackTracker[[#This Row],[Date]]-WEEKDAY(FeedbackTracker[[#This Row],[Date]],2)+1)) -> 46069
A35: 115042909248 | B35: 46071.393 | C35: Hogist technologies Pvt Ltd | D35: Accelerate Prime | E35: Chennai | F35: Sriram Chidambaram | G35: =AVERAGE(S35:T35) -> 2.5 | H35: Slightly useful | I35: Partly | J35: No | K35: Was just Ok. | L35: =IF(G35<=3,"Yes","No") -> Yes | N35: Received | O35: Misalignment | P35: Not suggested or connected by us. Was directly connected by HM 11-Mar-2026: Mentor was not aliginging with their problem and they want person from B2B | S35: =IF(H35="Extremely useful",5,IF(H35="Very useful",4,IF(H35="Moderately useful",3,IF(H35="Slightly useful",2,IF(H35="Not useful",1))))) -> 2 | T35: =IF(I35="Yes",5,IF(I35="Partly",3,IF(I35="No",1))) -> 3 | U35: =IF(J35="Yes",5,IF(J35="No",1)) -> 1 | V35: =IF(ISBLANK(FeedbackTracker[[#This Row],[Date]]),"",INT(FeedbackTracker[[#This Row],[Date]]-WEEKDAY(FeedbackTracker[[#This Row],[Date]],2)+1)) -> 46069
A36: 115042335711 | B36: 46070.741 | C36: Atreya Innovations | D36: Accelerate Prime | E36: Pune | F36: Sriram Chadambaram | G36: =AVERAGE(S36:T36) -> 4.5 | H36: Very useful | I36: Yes | J36: No | L36: =IF(G36<=3,"Yes","No") -> No | S36: =IF(H36="Extremely useful",5,IF(H36="Very useful",4,IF(H36="Moderately useful",3,IF(H36="Slightly useful",2,IF(H36="Not useful",1))))) -> 4 | T36: =IF(I36="Yes",5,IF(I36="Partly",3,IF(I36="No",1))) -> 5 | U36: =IF(J36="Yes",5,IF(J36="No",1)) -> 1 | V36: =IF(ISBLANK(FeedbackTracker[[#This Row],[Date]]),"",INT(FeedbackTracker[[#This Row],[Date]]-WEEKDAY(FeedbackTracker[[#This Row],[Date]],2)+1)) -> 46069
A37: 115042305484 | B37: 46070.691 | C37: Gyrodrive | D37: Accelerate Prime | E37: Pune | F37: Garima Mitra | G37: =AVERAGE(S37:T37) -> 4.5 | H37: Very useful | I37: Yes | J37: No | K37: We had a discussion and signed the term sheet and asked to share the term sheet. | L37: =IF(G37<=3,"Yes","No") -> No | S37: =IF(H37="Extremely useful",5,IF(H37="Very useful",4,IF(H37="Moderately useful",3,IF(H37="Slightly useful",2,IF(H37="Not useful",1))))) -> 4 | T37: =IF(I37="Yes",5,IF(I37="Partly",3,IF(I37="No",1))) -> 5 | U37: =IF(J37="Yes",5,IF(J37="No",1)) -> 1 | V37: =IF(ISBLANK(FeedbackTracker[[#This Row],[Date]]),"",INT(FeedbackTracker[[#This Row],[Date]]-WEEKDAY(FeedbackTracker[[#This Row],[Date]],2)+1)) -> 46069
A38: 115042304010 | B38: 46070.686 | C38: Frontierz | D38: Accelerate Prime | E38: Pune | F38: Sandeep Gupta | G38: =AVERAGE(S38:T38) -> 4.5 | H38: Very useful | I38: Yes | J38: No | K38: Overall it was good session and was a guy good. | L38: =IF(G38<=3,"Yes","No") -> No | S38: =IF(H38="Extremely useful",5,IF(H38="Very useful",4,IF(H38="Moderately useful",3,IF(H38="Slightly useful",2,IF(H38="Not useful",1))))) -> 4 | T38: =IF(I38="Yes",5,IF(I38="Partly",3,IF(I38="No",1))) -> 5 | U38: =IF(J38="Yes",5,IF(J38="No",1)) -> 1 | V38: =IF(ISBLANK(FeedbackTracker[[#This Row],[Date]]),"",INT(FeedbackTracker[[#This Row],[Date]]-WEEKDAY(FeedbackTracker[[#This Row],[Date]],2)+1)) -> 46069
A39: 115039714773 | B39: 46065.826 | C39: Leap Info | D39: Accelerate Core | E39: Pune | F39: Sriram Chidambaram | G39: =AVERAGE(S39:T39) -> 5 | H39: Extremely useful | I39: Yes | J39: No | K39: Highly practical and insightful | L39: =IF(G39<=3,"Yes","No") -> No | S39: =IF(H39="Extremely useful",5,IF(H39="Very useful",4,IF(H39="Moderately useful",3,IF(H39="Slightly useful",2,IF(H39="Not useful",1))))) -> 5 | T39: =IF(I39="Yes",5,IF(I39="Partly",3,IF(I39="No",1))) -> 5 | U39: =IF(J39="Yes",5,IF(J39="No",1)) -> 1 | V39: =IF(ISBLANK(FeedbackTracker[[#This Row],[Date]]),"",INT(FeedbackTracker[[#This Row],[Date]]-WEEKDAY(FeedbackTracker[[#This Row],[Date]],2)+1)) -> 46062
A40: 115034932805 | B40: 46058.5 | C40: Manufyx | D40: Accelerate Core | E40: Chennai | F40: Manu kumar | G40: =AVERAGE(S40:T40) -> 4.5 | H40: Very useful | I40: Yes | J40: No | L40: =IF(G40<=3,"Yes","No") -> No | M40: Reached out: Response Received | S40: =IF(H40="Extremely useful",5,IF(H40="Very useful",4,IF(H40="Moderately useful",3,IF(H40="Slightly useful",2,IF(H40="Not useful",1))))) -> 4 | T40: =IF(I40="Yes",5,IF(I40="Partly",3,IF(I40="No",1))) -> 5 | U40: =IF(J40="Yes",5,IF(J40="No",1)) -> 1 | V40: =IF(ISBLANK(FeedbackTracker[[#This Row],[Date]]),"",INT(FeedbackTracker[[#This Row],[Date]]-WEEKDAY(FeedbackTracker[[#This Row],[Date]],2)+1)) -> 46055
...

Sheet DUPLICATES
A1: Respondent ID | B1: Date | C1: Venture Name | D1: Mentor Name | E1: Overall Rating (1-5) | F1: How useful was this mentor session for your current business priorities? | G1: Actionability of Advice | H1: Follow-Up Requested? | I1: Verbatim Feedback | J1: Flagged (≤3)? | K1: Action Taken | L1: Response Category | M1: Feedback category | N1: Remarks | O1: Resolved? | P1: Reviewed In Stand-Up? | Q1: # How useful was this mentor session for your current business priorities? | R1: # Actionability of Advice | S1: # Follow-Up Requested? | T1: Date (Week)
A2: 115078086801 | B2: 46125.452 | C2: Zeus Engitech Private Limited | D2: Ankit Majumdar | E2: =AVERAGE(Q2:S2) -> 3 | F2: Moderately useful | G2: Yes | H2: No | I2: I selected “Moderately” because I would like to first implement the insights and suggestions shared, and then evaluate how effective they are. Overall, the session was very good. | J2: =IF(E2<=3,"Yes","No") -> Yes | L2: Duplicate | M2: Duplicate | N2: 13-Apr-2026: The mentor was good, but they wanted to see if the suggestions are truely useful at time of implementation. | Q2: =IF(F2="Extremely useful",5,IF(F2="Very useful",4,IF(F2="Moderately useful",3,IF(F2="Slightly useful",2,IF(F2="Not useful",1))))) -> 3 | R2: =IF(G2="Yes",5,IF(G2="Partly",3,IF(G2="No",1))) -> 5 | S2: =IF(H2="Yes",5,IF(H2="No",1)) -> 1 | T2: =IF(ISBLANK(FeedbackTracker[[#This Row],[Date]]),"",INT(FeedbackTracker[[#This Row],[Date]]-WEEKDAY(FeedbackTracker[[#This Row],[Date]],2)+1)) -> 46160
A3: 115042915820 | B3: 46071.413 | C3: Velaan Mart Pvt Ltd | D3: Ashish Mittal | E3: =AVERAGE(Q3:S3) -> 3.6666667 | F3: Extremely useful | G3: Yes | H3: No | I3: Really good session and we were able to raise funds | J3: =IF(E3<=3,"Yes","No") -> No | M3: Duplicate | Q3: =IF(F3="Extremely useful",5,IF(F3="Very useful",4,IF(F3="Moderately useful",3,IF(F3="Slightly useful",2,IF(F3="Not useful",1))))) -> 5 | R3: =IF(G3="Yes",5,IF(G3="Partly",3,IF(G3="No",1))) -> 5 | S3: =IF(H3="Yes",5,IF(H3="No",1)) -> 1 | T3: =IF(ISBLANK(FeedbackTracker[[#This Row],[Date]]),"",INT(FeedbackTracker[[#This Row],[Date]]-WEEKDAY(FeedbackTracker[[#This Row],[Date]],2)+1)) -> 46153
A4: 115042910595 | B4: 46071.409 | C4: Botminds.ai | D4: Mahesh Nataranjan | E4: =AVERAGE(Q4:S4) -> 3.3333333 | F4: Very useful | G4: Yes | H4: No | J4: =IF(E4<=3,"Yes","No") -> No | K4: Duplicate | L4: Duplicate | M4: Duplicate | N4: Duplicate | Q4: =IF(F4="Extremely useful",5,IF(F4="Very useful",4,IF(F4="Moderately useful",3,IF(F4="Slightly useful",2,IF(F4="Not useful",1))))) -> 4 | R4: =IF(G4="Yes",5,IF(G4="Partly",3,IF(G4="No",1))) -> 5 | S4: =IF(H4="Yes",5,IF(H4="No",1)) -> 1 | T4: =IF(ISBLANK(FeedbackTracker[[#This Row],[Date]]),"",INT(FeedbackTracker[[#This Row],[Date]]-WEEKDAY(FeedbackTracker[[#This Row],[Date]],2)+1)) -> 46153
A5: 115018962266 | B5: 46034.493 | C5: Sarumam Pharmacy | D5: Ajay Rungta | E5: =AVERAGE(Q5:S5) -> 4.3333333 | F5: Moderately useful | G5: Yes | H5: Yes | I5: He was able to identify what I needed and provided the solutions to me immediately. | J5: =IF(E5<=3,"Yes","No") -> No | L5: Received | M5: Duplicate | N5: 31-mar-2026: Required more session with mentor but after april | Q5: =IF(F5="Extremely useful",5,IF(F5="Very useful",4,IF(F5="Moderately useful",3,IF(F5="Slightly useful",2,IF(F5="Not useful",1))))) -> 3 | R5: =IF(G5="Yes",5,IF(G5="Partly",3,IF(G5="No",1))) -> 5 | S5: =IF(H5="Yes",5,IF(H5="No",1)) -> 5 | T5: =IF(ISBLANK(FeedbackTracker[[#This Row],[Date]]),"",INT(FeedbackTracker[[#This Row],[Date]]-WEEKDAY(FeedbackTracker[[#This Row],[Date]],2)+1)) -> 46153
A6: 115016986081 | B6: 46030.403 | C6: Eximburg International | D6: Sriram Chidambaram | E6: =AVERAGE(Q6:S6) -> 3 | F6: Moderately useful | G6: Yes | H6: No | I6: It was meaningful but I want to more about the valuation | J6: =IF(E6<=3,"Yes","No") -> Yes | L6: Duplicate | M6: Duplicate | N6: 31-Mar-206: Time was concern. Limitited time was there for the session | Q6: =IF(F6="Extremely useful",5,IF(F6="Very useful",4,IF(F6="Moderately useful",3,IF(F6="Slightly useful",2,IF(F6="Not useful",1))))) -> 3 | R6: =IF(G6="Yes",5,IF(G6="Partly",3,IF(G6="No",1))) -> 5 | S6: =IF(H6="Yes",5,IF(H6="No",1)) -> 1 | T6: =IF(ISBLANK(FeedbackTracker[[#This Row],[Date]]),"",INT(FeedbackTracker[[#This Row],[Date]]-WEEKDAY(FeedbackTracker[[#This Row],[Date]],2)+1)) -> 46153
A7: 115073800800 | B7: 46118.556 | C7: Eximburg International | D7: Kushagra Gupta | E7: =AVERAGE(Q7:S7) -> 2.3333333 | F7: Moderately useful | G7: Partly | H7: No | I7: Insight of Digital marketing | J7: =IF(E7<=3,"Yes","No") -> Yes | L7: Duplicate | M7: Duplicate | N7: 13-Apr-2026: The mentor was good, but they needed more support in digital marketing. Please suggest another mentor for this. Also, he’d like to connect with Kushagra Gupta for reviewing and auditing my Amazon account. | Q7: =IF(F7="Extremely useful",5,IF(F7="Very useful",4,IF(F7="Moderately useful",3,IF(F7="Slightly useful",2,IF(F7="Not useful",1))))) -> 3 | R7: =IF(G7="Yes",5,IF(G7="Partly",3,IF(G7="No",1))) -> 3 | S7: =IF(H7="Yes",5,IF(H7="No",1)) -> 1 | T7: =IF(ISBLANK(FeedbackTracker[[#This Row],[Date]]),"",INT(FeedbackTracker[[#This Row],[Date]]-WEEKDAY(FeedbackTracker[[#This Row],[Date]],2)+1)) -> 46153
A8: 115063541396 | B8: 46101.677 | C8: Tikitoro | D8: Gaurav Bansal | E8: =AVERAGE(Q8:S8) -> 3.6666667 | F8: Moderately useful | G8: Partly | H8: Yes | I8: The mentor was good and want to meet him even but will fix the agenda and if he agrees that he will be fit for that then only I need a call with him. | J8: =IF(E8<=3,"Yes","No") -> No | K8: Reached out: Response Received | L8: Received | M8: Duplicate | N8: 20-Mar-2026: Will check if the mentor is able give them desired outcome as in if he will agree on the agenda then want another call | Q8: =IF(F8="Extremely useful",5,IF(F8="Very useful",4,IF(F8="Moderately useful",3,IF(F8="Slightly useful",2,IF(F8="Not useful",1))))) -> 3 | R8: =IF(G8="Yes",5,IF(G8="Partly",3,IF(G8="No",1))) -> 3 | S8: =IF(H8="Yes",5,IF(H8="No",1)) -> 5 | T8: =IF(ISBLANK(FeedbackTracker[[#This Row],[Date]]),"",INT(FeedbackTracker[[#This Row],[Date]]-WEEKDAY(FeedbackTracker[[#This Row],[Date]],2)+1)) -> 46153
A9: 115056969460 | B9: 46092.403 | C9: Terrablu | D9: Anant Sood | E9: =AVERAGE(Q9:S9) -> 2.6666667 | F9: Very useful | G9: Partly | H9: No | I9: The session was good. The clearity with which Mr. sood was taking session was beyond imagination. | J9: =IF(E9<=3,"Yes","No") -> Yes | K9: No Response: Call Disconnected | L9: Received | M9: Duplicate | N9: 18-mar-2026: The venture expected immediate advice, but as it was an introductory call, the mentor focused on understanding the venture first. | Q9: =IF(F9="Extremely useful",5,IF(F9="Very useful",4,IF(F9="Moderately useful",3,IF(F9="Slightly useful",2,IF(F9="Not useful",1))))) -> 4 | R9: =IF(G9="Yes",5,IF(G9="Partly",3,IF(G9="No",1))) -> 3 | S9: =IF(H9="Yes",5,IF(H9="No",1)) -> 1 | T9: =IF(ISBLANK(FeedbackTracker[[#This Row],[Date]]),"",INT(FeedbackTracker[[#This Row],[Date]]-WEEKDAY(FeedbackTracker[[#This Row],[Date]],2)+1)) -> 46153
A10: 115042311879 | B10: 46070.693 | C10: Qarmatek | D10: Abhay Jajoo | E10: =AVERAGE(Q10:S10) -> 1 | F10: Not useful | G10: No | H10: No | I10: Not impressed with him | J10: =IF(E10<=3,"Yes","No") -> Yes | L10: Duplicate | M10: Duplicate | N10: Duplicate | Q10: =IF(F10="Extremely useful",5,IF(F10="Very useful",4,IF(F10="Moderately useful",3,IF(F10="Slightly useful",2,IF(F10="Not useful",1))))) -> 1 | R10: =IF(G10="Yes",5,IF(G10="Partly",3,IF(G10="No",1))) -> 1 | S10: =IF(H10="Yes",5,IF(H10="No",1)) -> 1 | T10: =IF(ISBLANK(FeedbackTracker[[#This Row],[Date]]),"",INT(FeedbackTracker[[#This Row],[Date]]-WEEKDAY(FeedbackTracker[[#This Row],[Date]],2)+1)) -> 46153
A11: 115030546274 | B11: 46051.625 | C11: Padcare Labs | D11: Mohanakrishnan P | E11: =AVERAGE(Q11:R11) -> 3 | F11: Moderately useful | G11: Partly | H11: No | J11: =IF(E11<=3,"Yes","No") -> Yes | L11: Duplicate | M11: Filled by Mistake | N11: 17-mar-2026: Venture filled by mistake and was impressed by mentor and is coordinating with the mentor directly for help over email. 16-Mar-2026: Venture rejected the call 11-Mar-2026: Asked to call tomorrow | Q11: =IF(F11="Extremely useful",5,IF(F11="Very useful",4,IF(F11="Moderately useful",3,IF(F11="Slightly useful",2,IF(F11="Not useful",1))))) -> 3 | R11: =IF(G11="Yes",5,IF(G11="Partly",3,IF(G11="No",1))) -> 3 | S11: =IF(H11="Yes",5,IF(H11="No",1)) -> 1 | T11: =IF(ISBLANK(FeedbackTracker[[#This Row],[Date]]),"",INT(FeedbackTracker[[#This Row],[Date]]-WEEKDAY(FeedbackTracker[[#This Row],[Date]],2)+1)) -> 46146
A12: 115023047140 | B12: 46040.427 | C12: Rupiya Finnovations Pvt Ltd | D12: Srinivas Yanamandra | E12: =AVERAGE(Q12:R12) -> 3 | F12: Moderately useful | G12: Partly | H12: Yes | J12: =IF(E12<=3,"Yes","No") -> Yes | L12: Received | M12: 1st Intro Call | N12: 16-Mar-2026: Mentor discussed quality aspects and was a genius guy, and want to connect with mentor again He was also very very helpful . Suggested changes founder is implying also. | Q12: =IF(F12="Extremely useful",5,IF(F12="Very useful",4,IF(F12="Moderately useful",3,IF(F12="Slightly useful",2,IF(F12="Not useful",1))))) -> 3 | R12: =IF(G12="Yes",5,IF(G12="Partly",3,IF(G12="No",1))) -> 3 | S12: =IF(H12="Yes",5,IF(H12="No",1)) -> 5 | T12: =IF(ISBLANK(FeedbackTracker[[#This Row],[Date]]),"",INT(FeedbackTracker[[#This Row],[Date]]-WEEKDAY(FeedbackTracker[[#This Row],[Date]],2)+1)) -> 46146

Sheet SESSION FEEDBACK PIVOT TABLE
A1: Response Category | B1: (Multiple Items)
A3: Row Labels | B3: Count of Venture Name
A4: 46146 | B4: 3
A5: Grand Total | B5: 3

Sheet Quality Dashboard
A1: QUALITY METRICS
A2: Total Sessions Rated | B2: =COUNTA(#REF!) -> 1
A3: Average Rating | B3: =IFERROR(AVERAGE(#REF!),0) -> 0
A4: Sessions Rated ≤ 3 (Negative) | B4: =COUNTIF(FeedbackTracker[Overall Rating (1-5)],"<=3") -> 26
A5: Sessions Rated 4-5 (Positive) | B5: =COUNTIF(FeedbackTracker[Overall Rating (1-5)],">=4") -> 70
A6: % Positive Sessions | B6: =IFERROR(B6/(B3),0) -> 0
A7: Follow-Up Requests | B7: =COUNTIF(FeedbackTracker[Follow-Up Requested?],"Yes") -> 31
A8: Flagged & Unresolved | B8: =COUNTIFS(FeedbackTracker[Flagged (≤3)?],"Yes",FeedbackTracker[Resolved?],"No") -> 0
A10: MENTOR QUALITY FLAGS
A11: (Track mentors with 3+ negative ratings for reassignment review)

Sheet Feedback from Mentor
A1: Respondent ID | B1: Collector ID | C1: Start Date | D1: End Date | E1: IP Address | F1: Email Address | G1: First Name | H1: Last Name | I1: Custom Data 1 | J1: Your Name | K1: Venture Name | L1: Mentee Name | M1: 1. Was the session agenda relevant to the startup’s current stage and specific needs? | N1: 2. Did the session agenda help you prepare effectively for the discussion? | O1: 3. Was the startup’s problem statement or request clearly articulated in the agenda? | P1: 4. Do you have any suggestions to improve the quality or format of the agenda or recommendations? | Q1: 5. How prepared and organized was your mentee for the session? | R1: 6. How engaged is your mentee during mentoring sessions, in terms of active participation and willingness to discuss challenges? | S1: 7. Is there anything the venture (or platform) could have done better to make this session more effective? | T1: 8. How would you like to rate the session? | U1: 9. How relevant were the recommended action items to the discussion during your session? | V1: 10. Were the suggested resources and tools aligned with the session topic and helpful for your next steps? | W1: 11. Is there any additional critical information you believe should be included in the post-session recommendations? | X1: RN Remarks | Y1: Category | Z1: Response Status | AA1: Start of Week | AB1: Trunc
A2: 115078155867 | B2: 438983145 | C2: 46125.606 | D2: 46125.609 | E2: 114.143.38.219 | J2: Garima Mitra | K2: Keepsake Automation Pvt Ltd | L2: Keepsake Automation | M2: Moderately Relevant | N2: Slightly helpful | O2: Not at all articulated | P2: Agenda has to be articulated. | Q2: Highly prepared | R2: Highly Engaged | S2: Set the Agenda. | T2: Neutral | U2: Moderately Relevant | V2: Moderately aligned | AA2: =IF(ISBLANK(FeedbackFrmMentor[[#This Row],[Start Date]]),"",FeedbackFrmMentor[[#This Row],[Start Date]]-WEEKDAY(FeedbackFrmMentor[[#This Row],[Start Date]],2)+1) -> 46125.606 | AB2: =TRUNC(FeedbackFrmMentor[[#This Row],[Start of Week]],0) -> 46125
A3: 115076821481 | B3: 438983145 | C3: 46122.53 | D3: 46122.531 | E3: 42.105.172.191 | J3: Ankit Majmudar | K3: Zeus Engitech Private Limited | L3: Delzad Khambata | M3: Extremely Relevant | N3: Extremely helpful | O3: Clearly articulated | P3: All was good | AA3: =IF(ISBLANK(FeedbackFrmMentor[[#This Row],[Start Date]]),"",FeedbackFrmMentor[[#This Row],[Start Date]]-WEEKDAY(FeedbackFrmMentor[[#This Row],[Start Date]],2)+1) -> 46118.53 | AB3: =TRUNC(FeedbackFrmMentor[[#This Row],[Start of Week]],0) -> 46118
A4: 115074566802 | B4: 438983145 | C4: 46119.659 | D4: 46119.66 | E4: 183.83.219.29 | J4: Kushagra Gupta | K4: Eximburg International | L4: Hitesh | M4: Moderately Relevant | N4: Moderately helpful | O4: Moderately articulated | Q4: Moderately prepared | R4: Somewhat Engaged | T4: Neutral | U4: Moderately Relevant | V4: Moderately aligned | AA4: =IF(ISBLANK(FeedbackFrmMentor[[#This Row],[Start Date]]),"",FeedbackFrmMentor[[#This Row],[Start Date]]-WEEKDAY(FeedbackFrmMentor[[#This Row],[Start Date]],2)+1) -> 46118.659 | AB4: =TRUNC(FeedbackFrmMentor[[#This Row],[Start of Week]],0) -> 46118
A5: 115068064794 | B5: 438983145 | C5: 46108.442 | D5: 46108.444 | E5: 122.172.82.128 | J5: Shridhar N Upadhye | K5: Tikitaro | L5: Prasanna Vasanadu | M5: Extremely Relevant | N5: Extremely helpful | O5: Exceptionally well-defined | P5: NIL | Q5: Extremely prepared | R5: Extremely Engaged | S5: NIL | T5: Very satisfied | U5: Extremely Relevant | V5: Extremely aligned | W5: NIL | AA5: =IF(ISBLANK(FeedbackFrmMentor[[#This Row],[Start Date]]),"",FeedbackFrmMentor[[#This Row],[Start Date]]-WEEKDAY(FeedbackFrmMentor[[#This Row],[Start Date]],2)+1) -> 46104.442 | AB5: =TRUNC(FeedbackFrmMentor[[#This Row],[Start of Week]],0) -> 46104
A6: 115067614145 | B6: 438983145 | C6: 46107.871 | D6: 46107.872 | E6: 106.219.225.66 | J6: Krishna Dorai | K6: Tikitaro | L6: Nagaprasanna | M6: Extremely Relevant | N6: Extremely helpful | O6: Exceptionally well-defined | Q6: Extremely prepared | R6: Extremely Engaged | T6: Very satisfied | U6: Very Relevant | V6: Extremely aligned | AA6: =IF(ISBLANK(FeedbackFrmMentor[[#This Row],[Start Date]]),"",FeedbackFrmMentor[[#This Row],[Start Date]]-WEEKDAY(FeedbackFrmMentor[[#This Row],[Start Date]],2)+1) -> 46104.871 | AB6: =TRUNC(FeedbackFrmMentor[[#This Row],[Start of Week]],0) -> 46104
A7: 115063561843 | B7: 438983145 | C7: 46101.726 | D7: 46101.728 | E7: 49.36.221.62 | J7: Gaurav Bansal | K7: Tikitaro | L7: Nagaprasanna Vasanadu | M7: Extremely Relevant | N7: Extremely helpful | O7: Clearly articulated | P7: None as of now, good initiative, keep rocking !!! | Q7: Highly prepared | R7: Extremely Engaged | S7: none as of now, stick to the current format, its working fine !! | T7: Very satisfied | U7: Extremely Relevant | V7: Extremely aligned | W7: None as of now | AA7: =IF(ISBLANK(FeedbackFrmMentor[[#This Row],[Start Date]]),"",FeedbackFrmMentor[[#This Row],[Start Date]]-WEEKDAY(FeedbackFrmMentor[[#This Row],[Start Date]],2)+1) -> 46097.726 | AB7: =TRUNC(FeedbackFrmMentor[[#This Row],[Start of Week]],0) -> 46097
A8: 115062975290 | B8: 438983145 | C8: 46100.832 | D8: 46100.837 | E8: 223.231.165.162 | J8: Shridhar N Upadhye | K8: Tikitaro | L8: Prasanna Vasanadu | M8: Extremely Relevant | N8: Extremely helpful | O8: Exceptionally well-defined | P8: Nothing as of now | Q8: Extremely prepared | R8: Extremely Engaged | S8: Nothing specific | T8: Very satisfied | U8: Extremely Relevant | V8: Extremely aligned | W8: Nothing specific | AA8: =IF(ISBLANK(FeedbackFrmMentor[[#This Row],[Start Date]]),"",FeedbackFrmMentor[[#This Row],[Start Date]]-WEEKDAY(FeedbackFrmMentor[[#This Row],[Start Date]],2)+1) -> 46097.832 | AB8: =TRUNC(FeedbackFrmMentor[[#This Row],[Start of Week]],0) -> 46097
A9: 115061108178 | B9: 438983145 | C9: 46098.418 | D9: 46098.429 | E9: 106.202.63.28 | J9: Shailendrasinh Rajput | K9: Bull AgriTech | L9: Divyajit | M9: Highly Relevant | N9: Moderately helpful | O9: Clearly articulated | P9: After introductory session i believe it should now in execution type and action oriented. | Q9: Extremely prepared | R9: Extremely Engaged | S9: Share more detail problems which understand not possible in one session | T9: Very satisfied | U9: Very Relevant | V9: Extremely aligned | W9: we should be clear what next action we be taking to improve the need of venture and how to go about with team work | AA9: =IF(ISBLANK(FeedbackFrmMentor[[#This Row],[Start Date]]),"",FeedbackFrmMentor[[#This Row],[Start Date]]-WEEKDAY(FeedbackFrmMentor[[#This Row],[Start Date]],2)+1) -> 46097.418 | AB9: =TRUNC(FeedbackFrmMentor[[#This Row],[Start of Week]],0) -> 46097
A10: 115060504360 | B10: 438983145 | C10: 46097.716 | D10: 46097.72 | E10: 171.76.80.255 | J10: Sivesh Kumar | K10: Bebe Burp | L10: Forgot | M10: Highly Relevant | N10: Very helpful | O10: Clearly articulated | P10: I guess it was ok, and not much is required. | Q10: Extremely prepared | R10: Highly Engaged | S10: It is not a one-time thing; mentorship requires more time than just a session. You should work more on it. Assigning mentees for longer periods with a mentor | T10: Satisfied | U10: Very Relevant | V10: Very aligned | W10: The mentee was looking more on the side of fundrasing than strategic support. He was a bit confused with GTM but mainly fundraising. It should be clear what the acceptance of mentee is, before entering the call. | AA10: =IF(ISBLANK(FeedbackFrmMentor[[#This Row],[Start Date]]),"",FeedbackFrmMentor[[#This Row],[Start Date]]-WEEKDAY(FeedbackFrmMentor[[#This Row],[Start Date]],2)+1) -> 46097.716 | AB10: =TRUNC(FeedbackFrmMentor[[#This Row],[Start of Week]],0) -> 46097
A11: 115060464576 | B11: 438983145 | C11: 46097.654 | D11: 46097.655 | E11: 122.166.190.164 | J11: Bharat Hudadalli | K11: Bebe Burp | L11: Chirag Gupta & Bharat Tiberwel | M11: Highly Relevant | N11: Extremely helpful | O11: Clearly articulated | P11: All good | Q11: Highly prepared | R11: Highly Engaged | S11: All good | T11: Satisfied | U11: Very Relevant | V11: Very aligned | W11: N/A | AA11: =IF(ISBLANK(FeedbackFrmMentor[[#This Row],[Start Date]]),"",FeedbackFrmMentor[[#This Row],[Start Date]]-WEEKDAY(FeedbackFrmMentor[[#This Row],[Start Date]],2)+1) -> 46097.654 | AB11: =TRUNC(FeedbackFrmMentor[[#This Row],[Start of Week]],0) -> 46097
A12: 115055433189 | B12: 438983145 | C12: 46090.623 | D12: 46090.625 | E12: 1.7.46.162 | J12: Bharat Hudadalli | K12: Bebe Burp | L12: Chirag Gupta & Bharat Tiberwal | M12: Extremely Relevant | N12: Very helpful | O12: Clearly articulated | P12: So far good! | Q12: Highly prepared | R12: Extremely Engaged | S12: All good! | T12: Very satisfied | U12: Very Relevant | V12: Extremely aligned | AA12: =IF(ISBLANK(FeedbackFrmMentor[[#This Row],[Start Date]]),"",FeedbackFrmMentor[[#This Row],[Start Date]]-WEEKDAY(FeedbackFrmMentor[[#This Row],[Start Date]],2)+1) -> 46090.623 | AB12: =TRUNC(FeedbackFrmMentor[[#This Row],[Start of Week]],0) -> 46090
C13: 46072.643 | J13: Jignesh Jain | K13: JustAct | L13: Rahul | M13: Moderately Relevant | N13: Moderately helpful | O13: Clearly articulated | AA13: =IF(ISBLANK(FeedbackFrmMentor[[#This Row],[Start Date]]),"",FeedbackFrmMentor[[#This Row],[Start Date]]-WEEKDAY(FeedbackFrmMentor[[#This Row],[Start Date]],2)+1) -> 46069.643 | AB13: =TRUNC(FeedbackFrmMentor[[#This Row],[Start of Week]],0) -> 46069
C14: 46072.65 | J14: Vignesh Narayanan | K14: Ask EVA | L14: Mohammad eshan | M14: Moderately Relevant | N14: Slightly helpful | O14: Not at all articulated | AA14: =IF(ISBLANK(FeedbackFrmMentor[[#This Row],[Start Date]]),"",FeedbackFrmMentor[[#This Row],[Start Date]]-WEEKDAY(FeedbackFrmMentor[[#This Row],[Start Date]],2)+1) -> 46069.65 | AB14: =TRUNC(FeedbackFrmMentor[[#This Row],[Start of Week]],0) -> 46069
C15: 46072.659 | J15: Dr. Naman Agarwal | K15: Leap Info | L15: Sudhir | M15: Extremely Relevant | N15: Extremely helpful | O15: Exceptionally well-defined | AA15: =IF(ISBLANK(FeedbackFrmMentor[[#This Row],[Start Date]]),"",FeedbackFrmMentor[[#This Row],[Start Date]]-WEEKDAY(FeedbackFrmMentor[[#This Row],[Start Date]],2)+1) -> 46069.659 | AB15: =TRUNC(FeedbackFrmMentor[[#This Row],[Start of Week]],0) -> 46069
C16: 46072.678 | J16: Abhay Jajoo | K16: Qarmatek | L16: Krunal Shah | M16: Moderately Relevant | N16: Moderately helpful | O16: Moderately articulated | AA16: =IF(ISBLANK(FeedbackFrmMentor[[#This Row],[Start Date]]),"",FeedbackFrmMentor[[#This Row],[Start Date]]-WEEKDAY(FeedbackFrmMentor[[#This Row],[Start Date]],2)+1) -> 46069.678 | AB16: =TRUNC(FeedbackFrmMentor[[#This Row],[Start of Week]],0) -> 46069
C17: 46072.683 | J17: Suhasini Barman | K17: REAGRI - NANOBEE BIOINNOVATIONS | L17: Reagri | M17: Extremely Relevant | N17: Extremely helpful | O17: Clearly articulated | AA17: =IF(ISBLANK(FeedbackFrmMentor[[#This Row],[Start Date]]),"",FeedbackFrmMentor[[#This Row],[Start Date]]-WEEKDAY(FeedbackFrmMentor[[#This Row],[Start Date]],2)+1) -> 46069.683 | AB17: =TRUNC(FeedbackFrmMentor[[#This Row],[Start of Week]],0) -> 46069
C18: 46072.746 | J18: Abhay Jajoo | K18: Servercake | L18: Amith Kumar Kalimuthu | M18: Extremely Relevant | N18: Extremely helpful | O18: Exceptionally well-defined | AA18: =IF(ISBLANK(FeedbackFrmMentor[[#This Row],[Start Date]]),"",FeedbackFrmMentor[[#This Row],[Start Date]]-WEEKDAY(FeedbackFrmMentor[[#This Row],[Start Date]],2)+1) -> 46069.746 | AB18: =TRUNC(FeedbackFrmMentor[[#This Row],[Start of Week]],0) -> 46069
C19: 46072.768 | J19: Ashesh D Shah | K19: Qarmatek | L19: Krunal Shah | M19: Extremely Relevant | N19: Extremely helpful | O19: Exceptionally well-defined | AA19: =IF(ISBLANK(FeedbackFrmMentor[[#This Row],[Start Date]]),"",FeedbackFrmMentor[[#This Row],[Start Date]]-WEEKDAY(FeedbackFrmMentor[[#This Row],[Start Date]],2)+1) -> 46069.768 | AB19: =TRUNC(FeedbackFrmMentor[[#This Row],[Start of Week]],0) -> 46069
C20: 46072.769 | J20: Nirmallya Roy Chowdhury | K20: Qarmatek | L20: Krunal Shah | M20: Extremely Relevant | N20: Extremely helpful | O20: Exceptionally well-defined | AA20: =IF(ISBLANK(FeedbackFrmMentor[[#This Row],[Start Date]]),"",FeedbackFrmMentor[[#This Row],[Start Date]]-WEEKDAY(FeedbackFrmMentor[[#This Row],[Start Date]],2)+1) -> 46069.769 | AB20: =TRUNC(FeedbackFrmMentor[[#This Row],[Start of Week]],0) -> 46069
C21: 46072.781 | J21: Deepak Srinivasan | K21: Vaultastic | L21: Tarun | M21: Highly Relevant | N21: Very helpful | O21: Clearly articulated | AA21: =IF(ISBLANK(FeedbackFrmMentor[[#This Row],[Start Date]]),"",FeedbackFrmMentor[[#This Row],[Start Date]]-WEEKDAY(FeedbackFrmMentor[[#This Row],[Start Date]],2)+1) -> 46069.781 | AB21: =TRUNC(FeedbackFrmMentor[[#This Row],[Start of Week]],0) -> 46069
C22: 46072.802 | J22: Srinivas Yanamandra | K22: Rupiya Finnovations Pvt Ltd | L22: Dhaval shah | M22: Extremely Relevant | N22: Extremely helpful | O22: Exceptionally well-defined | AA22: =IF(ISBLANK(FeedbackFrmMentor[[#This Row],[Start Date]]),"",FeedbackFrmMentor[[#This Row],[Start Date]]-WEEKDAY(FeedbackFrmMentor[[#This Row],[Start Date]],2)+1) -> 46069.802 | AB22: =TRUNC(FeedbackFrmMentor[[#This Row],[Start of Week]],0) -> 46069
C23: 46072.808 | J23: Srinivas Yanamandra | K23: Hreedan Lifestyle | L23: Rekharani bhanudas mane | M23: Extremely Relevant | N23: Extremely helpful | O23: Exceptionally well-defined | AA23: =IF(ISBLANK(FeedbackFrmMentor[[#This Row],[Start Date]]),"",FeedbackFrmMentor[[#This Row],[Start Date]]-WEEKDAY(FeedbackFrmMentor[[#This Row],[Start Date]],2)+1) -> 46069.808 | AB23: =TRUNC(FeedbackFrmMentor[[#This Row],[Start of Week]],0) -> 46069
C24: 46072.81 | J24: Kavya Dehulia | K24: Stembotix | L24: Sagar | M24: Not Relevant | N24: Not at all helpful | O24: Not at all articulated | AA24: =IF(ISBLANK(FeedbackFrmMentor[[#This Row],[Start Date]]),"",FeedbackFrmMentor[[#This Row],[Start Date]]-WEEKDAY(FeedbackFrmMentor[[#This Row],[Start Date]],2)+1) -> 46069.81 | AB24: =TRUNC(FeedbackFrmMentor[[#This Row],[Start of Week]],0) -> 46069
... C32: 46073.411 | J32: Manu Kumar | K32: Raptee Energy Pvt Ltd | L32: Dinesh Arjun | M32: Highly Relevant | N32: Extremely helpful | O32: Exceptionally well-defined | AA32: =IF(ISBLANK(FeedbackFrmMentor[[#This Row],[Start Date]]),"",FeedbackFrmMentor[[#This Row],[Start Date]]-WEEKDAY(FeedbackFrmMentor[[#This Row],[Start Date]],2)+1) -> 46069.411 | AB32: =TRUNC(FeedbackFrmMentor[[#This Row],[Start of Week]],0) -> 46069

Sheet Feedback from Mentor Pivot 
A1: Trunc | B1: Count of Venture Name
A2: 46069 | B2: 20
A3: 46090 | B3: 1
A4: 46097 | B4: 5
A5: 46104 | B5: 2
A6: 46118 | B6: 2
A7: 46125 | B7: 1
A8: Grand Total | B8: 31

Sheet NPS Calculation
A2: Feedback from Founders | B2: # | E2: Mentor Workbench NPS | F2: #
A3: Not useful | B3: =COUNTIFS(FeedbackTracker[How useful was this mentor session for your current business priorities?],'NPS Calculation'!A3,FeedbackTracker[Response Category],"<>Duplicate") -> 2 | E3: Not Relevant | F3: =COUNTIFS(FeedbackFrmMentor[1. Was the session agenda relevant to the startup’s current stage and specific needs?],'NPS Calculation'!E3) -> 1
A4: Slightly useful | B4: =COUNTIFS(FeedbackTracker[How useful was this mentor session for your current business priorities?],'NPS Calculation'!A4,FeedbackTracker[Response Category],"<>Duplicate") -> 7 | E4: Slightly Relevant | F4: =COUNTIFS(FeedbackFrmMentor[1. Was the session agenda relevant to the startup’s current stage and specific needs?],'NPS Calculation'!E4) -> 0
A5: Moderately useful | B5: =COUNTIFS(FeedbackTracker[How useful was this mentor session for your current business priorities?],'NPS Calculation'!A5,FeedbackTracker[Response Category],"<>Duplicate") -> 21 | E5: Moderately Relevant | F5: =COUNTIFS(FeedbackFrmMentor[1. Was the session agenda relevant to the startup’s current stage and specific needs?],'NPS Calculation'!E5) -> 5
A6: Very useful | B6: =COUNTIFS(FeedbackTracker[How useful was this mentor session for your current business priorities?],'NPS Calculation'!A6,FeedbackTracker[Response Category],"<>Duplicate") -> 54 | E6: Highly Relevant | F6: =COUNTIFS(FeedbackFrmMentor[1. Was the session agenda relevant to the startup’s current stage and specific needs?],'NPS Calculation'!E6) -> 6
A7: Extremely useful | B7: =COUNTIFS(FeedbackTracker[How useful was this mentor session for your current business priorities?],'NPS Calculation'!A7,FeedbackTracker[Response Category],"<>Duplicate") -> 22 | E7: Extremely Relevant | F7: =COUNTIFS(FeedbackFrmMentor[1. Was the session agenda relevant to the startup’s current stage and specific needs?],'NPS Calculation'!E7) -> 19
A8: SUM | B8: =SUM(B3:B7) -> 106 | E8: SUM | F8: =SUM(F3:F7) -> 31
A10: Promoter | B10: =B6+B7 -> 76 | E10: Promoter | F10: =F6+F7 -> 25
A11: Passive | B11: =B5+B4 -> 28 | E11: Passive | F11: =F5+F4 -> 5
A12: Detractor | B12: =B3 -> 2 | E12: Detractor | F12: =F3 -> 1
A14: NPS | B14: =((B10-B12)/B8)*100 -> 69.811321 | E14: NPS | F14: =((F10-F12)/F8)*100 -> 77.419355
A18: Promoter | B18: 46 | C18: 78
A19: Passive | B19: 37 | C19: 11
A20: Detractor | B20: 14 | C20: 8
